<?xml version="1.0"?>
<robot name="drone_core" xmlns:xacro="http://www.ros.org/wiki/xacro">
  <!-- Expected params -->
  <xacro:macro name="drone_core" params="robot_name:=match_drohne1 namespace:=">

    <!-- BASE LINK -->
    <link name="base_link">
      <inertial>
        <origin xyz="0 0 0" rpy="0 0 0"/>
        <mass value="2.0"/>
        <inertia 
          ixx="0.02166666666666667" ixy="0" ixz="0"
          iyy="0.02166666666666667" iyz="0"  izz="0.04000000000000001"/>
      </inertial>

      <visual name="base_link_visual">
        <origin xyz="0 0 -0.35" rpy="0 0 3.141592654"/>
        <geometry>
          <!-- <mesh filename="meshes/Drohnen-Modell.glb" scale="1 1 1"/> -->
          <mesh filename="package://match_slam/description/meshes/Drohnen-Modell.stl" scale="1 1 1"/>
        </geometry>
      </visual>
      
      <!-- <visual name="base_link_visual2">
        <origin xyz="0 0 -0.06" rpy="0 0 1.570796327"/>
        <geometry>
          <mesh filename="package://match_slam/description/meshes/Marvin.stl" scale="1 1 1"/>
        </geometry>
      </visual> -->

      <visual name="5010_motor_base_0">
        <origin xyz="0.23 0.23 0.032" rpy="0 0 -0.45"/>
        <geometry>
          <mesh filename="package://match_slam/description/x500/x500_base/meshes/5010Base.dae" scale="1 1 1"/>
        </geometry>
      </visual>
      <visual name="5010_motor_base_1">
        <origin xyz="-0.23 0.23 0.032" rpy="0 0 -0.45"/>
        <geometry>
          <mesh filename="package://match_slam/description/x500/x500_base/meshes/5010Base.dae" scale="1 1 1"/>
        </geometry>
      </visual>
      <visual name="5010_motor_base_2">
        <origin xyz="0.23 -0.23 0.032" rpy="0 0 -0.45"/>
        <geometry>
          <mesh filename="package://match_slam/description/x500/x500_base/meshes/5010Base.dae" scale="1 1 1"/>
        </geometry>
      </visual>
      <visual name="5010_motor_base_3">
        <origin xyz="-0.23 -0.23 0.032" rpy="0 0 -0.45"/>
        <geometry>
          <mesh filename="package://match_slam/description/x500/x500_base/meshes/5010Base.dae" scale="1 1 1"/>
        </geometry>
      </visual>

      <visual name="NXP_FMUK66_FRONT">
        <origin xyz="0.047 0.001 0.043" rpy="1 0 1.57"/>
        <geometry>
          <box size="0.013 0.007 0.001"/>
        </geometry>
        <material name="nxp_fmuk66_front">
          <texture filename="package://match_slam/description/x500/x500_base/materials/textures/nxp.png"/>
        </material>
      </visual>
      <visual name="NXP_FMUK66_TOP">
        <origin xyz="-0.023 0 0.0515" rpy="0 0 -1.57"/>
        <geometry>
          <box size="0.013 0.007 0.001"/>
        </geometry>
        <material name="nxp_fmuk66_top">
          <texture filename="package://match_slam/description/x500/x500_base/materials/textures/nxp.png"/>
        </material>
      </visual>
      <visual name="RDDRONE_FMUK66_TOP">
        <origin xyz="-0.03 0 0.0515" rpy="0 0 -1.57"/>
        <geometry>
          <box size="0.032 0.0034 0.001"/>
        </geometry>
        <material name="rddrone_fmuk66_top">
          <texture filename="package://match_slam/description/x500/x500_base/materials/textures/rd.png"/>
        </material>
      </visual>

      <collision name="base_link_collision_0">
        <origin xyz="0 0 0.007" rpy="0 0 0"/>
        <geometry>
          <box size="0.35355339059327373 0.35355339059327373 0.05"/>
        </geometry>
      </collision>
      <collision name="base_link_collision_1">
        <origin xyz="0 -0.098 -0.123" rpy="-0.35 0 0"/>
        <geometry>
          <box size="0.015 0.015 0.21"/>
        </geometry>
      </collision>
      <collision name="base_link_collision_2">
        <origin xyz="0 0.098 -0.123" rpy="0.35 0 0"/>
        <geometry>
          <box size="0.015 0.015 0.21"/>
        </geometry>
      </collision>
      <collision name="base_link_collision_3">
        <origin xyz="0 -0.132 -0.2195" rpy="0 0 0"/>
        <geometry>
          <box size="0.25 0.015 0.015"/>
        </geometry>
      </collision>
      <collision name="base_link_collision_4">
        <origin xyz="0 0.132 -0.2195" rpy="0 0 0"/>
        <geometry>
          <box size="0.25 0.015 0.015"/>
        </geometry>
      </collision>
    </link>

    <!-- ROTOR 0 -->
    <link name="rotor_0">
      <inertial>
        <origin xyz="0 0 0" rpy="0 0 0"/>
        <mass value="0.016076923076923075"/>
        <inertia 
          ixx="3.8464910483993325e-07" ixy="0" ixz="0"
          iyy="2.6115851691700804e-05" iyz="0" izz="2.649858234714004e-05"/>
      </inertial>
      <visual name="rotor_0_visual">
        <origin xyz="-0.022 -0.14638461538461536 -0.016" rpy="0 0 0"/>
        <geometry>
          <mesh filename="package://match_slam/description/x500/x500_base/meshes/1345_prop_ccw.stl" scale="0.8461538461538461 0.8461538461538461 0.8461538461538461"/>
        </geometry>
      </visual>
      <visual name="rotor_0_visual_motor_bell">
        <origin xyz="0 0 -0.032" rpy="0 0 0"/>
        <geometry>
          <mesh filename="package://match_slam/description/x500/x500_base/meshes/5010Bell.dae" scale="1 1 1"/>
        </geometry>
      </visual>
      <collision name="rotor_0_collision">
        <origin xyz="0 0 0" rpy="0 0 0"/>
        <geometry>
          <box size="0.2792307692307692 0.016923076923076923 0.0008461538461538462"/>
        </geometry>
      </collision>
    </link>
    <joint name="rotor_0_joint" type="continuous">
      <parent link="base_link"/>
      <child link="rotor_0"/>
      <origin xyz="0.23 -0.23 0.06" rpy="0 0 0"/>
      <axis xyz="0 0 1"/>
    </joint>

    <!-- ROTOR 1 -->
    <link name="rotor_1">
      <inertial>
        <origin xyz="0 0 0" rpy="0 0 0"/>
        <mass value="0.016076923076923075"/>
        <inertia 
          ixx="3.8464910483993325e-07" ixy="0" ixz="0"
          iyy="2.6115851691700804e-05" iyz="0" izz="2.649858234714004e-05"/>
      </inertial>
      <visual name="rotor_1_visual">
        <origin xyz="-0.022 -0.14638461538461536 -0.016" rpy="0 0 0"/>
        <geometry>
          <mesh filename="package://match_slam/description/x500/x500_base/meshes/1345_prop_ccw.stl" scale="0.8461538461538461 0.8461538461538461 0.8461538461538461"/>
        </geometry>
      </visual>
      <visual name="rotor_1_visual_motor_top">
        <origin xyz="0 0 -0.032" rpy="0 0 0"/>
        <geometry>
          <mesh filename="package://match_slam/description/x500/x500_base/meshes/5010Bell.dae" scale="1 1 1"/>
        </geometry>
      </visual>
      <collision name="rotor_1_collision">
        <origin xyz="0 0 0" rpy="0 0 0"/>
        <geometry>
          <box size="0.2792307692307692 0.016923076923076923 0.0008461538461538462"/>
        </geometry>
      </collision>
    </link>
    <joint name="rotor_1_joint" type="continuous">
      <parent link="base_link"/>
      <child link="rotor_1"/>
      <origin xyz="-0.23 0.23 0.06" rpy="0 0 0"/>
      <axis xyz="0 0 1"/>
    </joint>

    <!-- ROTOR 2 -->
    <link name="rotor_2">
      <inertial>
        <origin xyz="0 0 0" rpy="0 0 0"/>
        <mass value="0.016076923076923075"/>
        <inertia 
          ixx="3.8464910483993325e-07" ixy="0" ixz="0"
          iyy="2.6115851691700804e-05" iyz="0" izz="2.649858234714004e-05"/>
      </inertial>
      <visual name="rotor_2_visual">
        <origin xyz="-0.022 -0.14638461538461536 -0.016" rpy="0 0 0"/>
        <geometry>
          <mesh filename="package://match_slam/description/x500/x500_base/meshes/1345_prop_cw.stl" scale="0.8461538461538461 0.8461538461538461 0.8461538461538461"/>
        </geometry>
      </visual>
      <visual name="rotor_2_visual_motor_top">
        <origin xyz="0 0 -0.032" rpy="0 0 0"/>
        <geometry>
          <mesh filename="package://match_slam/description/x500/x500_base/meshes/5010Bell.dae" scale="1 1 1"/>
        </geometry>
      </visual>
      <collision name="rotor_2_collision">
        <origin xyz="0 0 0" rpy="0 0 0"/>
        <geometry>
          <box size="0.2792307692307692 0.016923076923076923 0.0008461538461538462"/>
        </geometry>
      </collision>
    </link>
    <joint name="rotor_2_joint" type="continuous">
      <parent link="base_link"/>
      <child link="rotor_2"/>
      <origin xyz="0.23 0.23 0.06" rpy="0 0 0"/>
      <axis xyz="0 0 1"/>
    </joint>

    <!-- ROTOR 3 -->
    <link name="rotor_3">
      <inertial>
        <origin xyz="0 0 0" rpy="0 0 0"/>
        <mass value="0.016076923076923075"/>
        <inertia 
          ixx="3.8464910483993325e-07" ixy="0" ixz="0"
          iyy="2.6115851691700804e-05" iyz="0" izz="2.649858234714004e-05"/>
      </inertial>
      <visual name="rotor_3_visual">
        <origin xyz="-0.022 -0.14638461538461536 -0.016" rpy="0 0 0"/>
        <geometry>
          <mesh filename="package://match_slam/description/x500/x500_base/meshes/1345_prop_cw.stl" scale="0.8461538461538461 0.8461538461538461 0.8461538461538461"/>
        </geometry>
      </visual>
      <visual name="rotor_3_visual_motor_top">
        <origin xyz="0 0 -0.032" rpy="0 0 0"/>
        <geometry>
          <mesh filename="package://match_slam/description/x500/x500_base/meshes/5010Bell.dae" scale="1 1 1"/>
        </geometry>
      </visual>
      <collision name="rotor_3_collision">
        <origin xyz="0 0 0" rpy="0 0 0"/>
        <geometry>
          <box size="0.2792307692307692 0.016923076923076923 0.0008461538461538462"/>
        </geometry>
      </collision>
    </link>
    <joint name="rotor_3_joint" type="continuous">
      <parent link="base_link"/>
      <child link="rotor_3"/>
      <origin xyz="-0.23 -0.23 0.06" rpy="0 0 0"/>
      <axis xyz="0 0 1"/>
    </joint>

  </xacro:macro>
</robot>